2025-05-11 18:28:49,047 - INFO - [test_analyze_paper.py:33] - === 단일 파일 분석 테스트 시작 ===
2025-05-11 18:28:49,049 - INFO - [test_analyze_paper.py:38] - 테스트 환경 설정 완료: 입력 폴더=test_input, 출력 폴더=test_result, 로그 폴더=test_logs
2025-05-11 18:28:49,050 - INFO - [test_analyze_paper.py:48] - 테스트 파일 복사 완료: test_input\A business model template for AI solutions.pdf
2025-05-11 18:28:49,066 - INFO - [test_analyze_paper.py:58] - 프롬프트 템플릿과 분석 키 로드 완료
2025-05-11 18:28:49,066 - INFO - [test_analyze_paper.py:61] - 파일 분석 시작: test_input\A business model template for AI solutions.pdf
2025-05-11 18:28:49,067 - INFO - [analyze_paper.py:68] - 'A business model template for AI solutions.pdf' 파일을 업로드하는 중...
2025-05-11 18:28:49,853 - DEBUG - [discovery.py:1258] - URL being requested: POST https://generativelanguage.googleapis.com/upload/v1beta/files?key=AIzaSyB1te7hQnMp6v5nyQgv_F2uUMjTonbSjDs&alt=json&uploadType=resumable
2025-05-11 18:28:53,287 - INFO - [analyze_paper.py:71] - -> 파일 업로드 완료: A business model template for AI solutions.pdf (URI: https://generativelanguage.googleapis.com/v1beta/files/sqgbigppdoeh)
2025-05-11 18:28:53,288 - DEBUG - [analyze_paper.py:72] - 파일 메타데이터: 크기=337262 bytes, 생성일=2025-05-11 18:28:49.048837
2025-05-11 18:28:55,289 - INFO - [analyze_paper.py:83] - Gemini API로 PDF 분석 시작...
2025-05-11 18:28:55,289 - DEBUG - [analyze_paper.py:86] - 모델 초기화 완료: gemini-2.0-pro
2025-05-11 18:28:55,731 - ERROR - [analyze_paper.py:93] - 오류: PDF 분석 중 문제 발생 - 404 models/gemini-2.0-pro is not found for API version v1beta, or is not supported for generateContent. Call ListModels to see the list of available models and their supported methods.
Traceback (most recent call last):
  File "C:\Users\javam\OneDrive\dev\analyze-paper\analyze_paper.py", line 88, in analyze_pdf_with_gemini
    response = model.generate_content([prompt, pdf_file])
  File "C:\Users\javam\AppData\Local\Packages\PythonSoftwareFoundation.Python.3.13_qbz5n2kfra8p0\LocalCache\local-packages\Python313\site-packages\google\generativeai\generative_models.py", line 331, in generate_content
    response = self._client.generate_content(
        request,
        **request_options,
    )
  File "C:\Users\javam\AppData\Local\Packages\PythonSoftwareFoundation.Python.3.13_qbz5n2kfra8p0\LocalCache\local-packages\Python313\site-packages\google\ai\generativelanguage_v1beta\services\generative_service\client.py", line 835, in generate_content
    response = rpc(
        request,
    ...<2 lines>...
        metadata=metadata,
    )
  File "C:\Users\javam\AppData\Local\Packages\PythonSoftwareFoundation.Python.3.13_qbz5n2kfra8p0\LocalCache\local-packages\Python313\site-packages\google\api_core\gapic_v1\method.py", line 131, in __call__
    return wrapped_func(*args, **kwargs)
  File "C:\Users\javam\AppData\Local\Packages\PythonSoftwareFoundation.Python.3.13_qbz5n2kfra8p0\LocalCache\local-packages\Python313\site-packages\google\api_core\retry\retry_unary.py", line 294, in retry_wrapped_func
    return retry_target(
        target,
    ...<3 lines>...
        on_error=on_error,
    )
  File "C:\Users\javam\AppData\Local\Packages\PythonSoftwareFoundation.Python.3.13_qbz5n2kfra8p0\LocalCache\local-packages\Python313\site-packages\google\api_core\retry\retry_unary.py", line 156, in retry_target
    next_sleep = _retry_error_helper(
        exc,
    ...<6 lines>...
        timeout,
    )
  File "C:\Users\javam\AppData\Local\Packages\PythonSoftwareFoundation.Python.3.13_qbz5n2kfra8p0\LocalCache\local-packages\Python313\site-packages\google\api_core\retry\retry_base.py", line 214, in _retry_error_helper
    raise final_exc from source_exc
  File "C:\Users\javam\AppData\Local\Packages\PythonSoftwareFoundation.Python.3.13_qbz5n2kfra8p0\LocalCache\local-packages\Python313\site-packages\google\api_core\retry\retry_unary.py", line 147, in retry_target
    result = target()
  File "C:\Users\javam\AppData\Local\Packages\PythonSoftwareFoundation.Python.3.13_qbz5n2kfra8p0\LocalCache\local-packages\Python313\site-packages\google\api_core\timeout.py", line 130, in func_with_timeout
    return func(*args, **kwargs)
  File "C:\Users\javam\AppData\Local\Packages\PythonSoftwareFoundation.Python.3.13_qbz5n2kfra8p0\LocalCache\local-packages\Python313\site-packages\google\api_core\grpc_helpers.py", line 78, in error_remapped_callable
    raise exceptions.from_grpc_error(exc) from exc
google.api_core.exceptions.NotFound: 404 models/gemini-2.0-pro is not found for API version v1beta, or is not supported for generateContent. Call ListModels to see the list of available models and their supported methods.
2025-05-11 18:28:55,802 - INFO - [test_analyze_paper.py:65] - 파일 분석 완료
2025-05-11 18:28:55,802 - DEBUG - [test_analyze_paper.py:66] - 분석 결과: {'논문 제목': 'A business model template for AI solutions.pdf', '핵심 내용': '처리 시작', '비즈니스 모델 캔버스(BMC) 활용 여부': '처리 시작', 'AI의 특징': '처리 시작', '고객 세그먼트': '처리 시작', '가치 제안': '처리 시작', '채널': '처리 시작', '고객 관계': '처리 시작', '수익 흐름': '처리 시작', '핵심 자원': '처리 시작', '핵심 활동': '처리 시작', '핵심 파트너십': '처리 시작', '비용 구조': '처리 시작', '추가영역 제시': '처리 시작', '비즈니스 캔버스 모델의 틀 변경 여부': '처리 시작', '기타': '처리 시작', '오류': 'API 응답 없음'}
2025-05-11 18:28:55,803 - INFO - [test_analyze_paper.py:76] - === 단일 파일 분석 테스트 종료 ===
